Creating MinibatchAlgorithm...
Starting training with MinibatchAlgorithm...
Training batch size: 1
Number of threads: 20
Evaluating agent (iteration 0): 100%|â–ˆâ–ˆâ–ˆâ–ˆâ–ˆâ–ˆâ–ˆâ–ˆâ–ˆâ–ˆâ–ˆâ–ˆâ–ˆâ–ˆâ–ˆâ–ˆâ–ˆâ–ˆâ–ˆâ–ˆâ–ˆâ–ˆâ–ˆâ–ˆâ–ˆâ–ˆâ–ˆâ–ˆâ–ˆâ–ˆâ–ˆâ–ˆâ–ˆâ–ˆâ–ˆâ–ˆâ–ˆâ–ˆâ–ˆâ–ˆâ–ˆâ–ˆâ–ˆâ–ˆâ–ˆâ–ˆâ–ˆâ–ˆâ–ˆâ–ˆâ–ˆâ–ˆâ–ˆâ–ˆâ–ˆâ–ˆâ–ˆâ–ˆâ–ˆâ–ˆâ–ˆâ–ˆâ–ˆâ–ˆâ–ˆâ–ˆâ–ˆâ–ˆâ–ˆâ–ˆâ–ˆâ–ˆâ–ˆâ–ˆâ–ˆâ–ˆâ–ˆâ–ˆâ–ˆâ–ˆâ–ˆâ–ˆâ–ˆâ–ˆâ–ˆ| 3/3 [00:31<00:00, 10.38s/it]
[Step 0] [92mTest score: 0.3333333333333333[0m
Forward pass (batch size: 1): 100%|â–ˆâ–ˆâ–ˆâ–ˆâ–ˆâ–ˆâ–ˆâ–ˆâ–ˆâ–ˆâ–ˆâ–ˆâ–ˆâ–ˆâ–ˆâ–ˆâ–ˆâ–ˆâ–ˆâ–ˆâ–ˆâ–ˆâ–ˆâ–ˆâ–ˆâ–ˆâ–ˆâ–ˆâ–ˆâ–ˆâ–ˆâ–ˆâ–ˆâ–ˆâ–ˆâ–ˆâ–ˆâ–ˆâ–ˆâ–ˆâ–ˆâ–ˆâ–ˆâ–ˆâ–ˆâ–ˆâ–ˆâ–ˆâ–ˆâ–ˆâ–ˆâ–ˆâ–ˆâ–ˆâ–ˆâ–ˆâ–ˆâ–ˆâ–ˆâ–ˆâ–ˆâ–ˆâ–ˆâ–ˆâ–ˆâ–ˆâ–ˆâ–ˆâ–ˆâ–ˆâ–ˆâ–ˆâ–ˆâ–ˆâ–ˆâ–ˆâ–ˆâ–ˆâ–ˆâ–ˆâ–ˆâ–ˆâ–ˆâ–ˆâ–ˆâ–ˆâ–ˆ| 1/1 [00:37<00:00, 37.27s/it]
Forward pass (batch size: 1): 100%|â–ˆâ–ˆâ–ˆâ–ˆâ–ˆâ–ˆâ–ˆâ–ˆâ–ˆâ–ˆâ–ˆâ–ˆâ–ˆâ–ˆâ–ˆâ–ˆâ–ˆâ–ˆâ–ˆâ–ˆâ–ˆâ–ˆâ–ˆâ–ˆâ–ˆâ–ˆâ–ˆâ–ˆâ–ˆâ–ˆâ–ˆâ–ˆâ–ˆâ–ˆâ–ˆâ–ˆâ–ˆâ–ˆâ–ˆâ–ˆâ–ˆâ–ˆâ–ˆâ–ˆâ–ˆâ–ˆâ–ˆâ–ˆâ–ˆâ–ˆâ–ˆâ–ˆâ–ˆâ–ˆâ–ˆâ–ˆâ–ˆâ–ˆâ–ˆâ–ˆâ–ˆâ–ˆâ–ˆâ–ˆâ–ˆâ–ˆâ–ˆâ–ˆâ–ˆâ–ˆâ–ˆâ–ˆâ–ˆâ–ˆâ–ˆâ–ˆâ–ˆâ–ˆâ–ˆâ–ˆâ–ˆâ–ˆâ–ˆâ–ˆâ–ˆâ–ˆâ–ˆ| 1/1 [00:38<00:00, 38.90s/it]
Forward pass (batch size: 1): 100%|â–ˆâ–ˆâ–ˆâ–ˆâ–ˆâ–ˆâ–ˆâ–ˆâ–ˆâ–ˆâ–ˆâ–ˆâ–ˆâ–ˆâ–ˆâ–ˆâ–ˆâ–ˆâ–ˆâ–ˆâ–ˆâ–ˆâ–ˆâ–ˆâ–ˆâ–ˆâ–ˆâ–ˆâ–ˆâ–ˆâ–ˆâ–ˆâ–ˆâ–ˆâ–ˆâ–ˆâ–ˆâ–ˆâ–ˆâ–ˆâ–ˆâ–ˆâ–ˆâ–ˆâ–ˆâ–ˆâ–ˆâ–ˆâ–ˆâ–ˆâ–ˆâ–ˆâ–ˆâ–ˆâ–ˆâ–ˆâ–ˆâ–ˆâ–ˆâ–ˆâ–ˆâ–ˆâ–ˆâ–ˆâ–ˆâ–ˆâ–ˆâ–ˆâ–ˆâ–ˆâ–ˆâ–ˆâ–ˆâ–ˆâ–ˆâ–ˆâ–ˆâ–ˆâ–ˆâ–ˆâ–ˆâ–ˆâ–ˆâ–ˆâ–ˆâ–ˆâ–ˆ| 1/1 [00:13<00:00, 13.57s/it]
Forward pass (batch size: 1): 100%|â–ˆâ–ˆâ–ˆâ–ˆâ–ˆâ–ˆâ–ˆâ–ˆâ–ˆâ–ˆâ–ˆâ–ˆâ–ˆâ–ˆâ–ˆâ–ˆâ–ˆâ–ˆâ–ˆâ–ˆâ–ˆâ–ˆâ–ˆâ–ˆâ–ˆâ–ˆâ–ˆâ–ˆâ–ˆâ–ˆâ–ˆâ–ˆâ–ˆâ–ˆâ–ˆâ–ˆâ–ˆâ–ˆâ–ˆâ–ˆâ–ˆâ–ˆâ–ˆâ–ˆâ–ˆâ–ˆâ–ˆâ–ˆâ–ˆâ–ˆâ–ˆâ–ˆâ–ˆâ–ˆâ–ˆâ–ˆâ–ˆâ–ˆâ–ˆâ–ˆâ–ˆâ–ˆâ–ˆâ–ˆâ–ˆâ–ˆâ–ˆâ–ˆâ–ˆâ–ˆâ–ˆâ–ˆâ–ˆâ–ˆâ–ˆâ–ˆâ–ˆâ–ˆâ–ˆâ–ˆâ–ˆâ–ˆâ–ˆâ–ˆâ–ˆâ–ˆâ–ˆ| 1/1 [01:08<00:00, 68.56s/it]
Error during training: litellm.InternalServerError: litellm.InternalServerError: VertexAIException - {
  "error": {
    "code": 503,
    "message": "The model is overloaded. Please try again later.",
    "status": "UNAVAILABLE"
  }
}
Traceback (most recent call last):
  File "/opt/anaconda3/envs/tau/lib/python3.12/site-packages/litellm/llms/vertex_ai/gemini/vertex_and_google_ai_studio_gemini.py", line 1711, in completion
    response = client.post(url=url, headers=headers, json=data)  # type: ignore
               ^^^^^^^^^^^^^^^^^^^^^^^^^^^^^^^^^^^^^^^^^^^^^^^^
  File "/opt/anaconda3/envs/tau/lib/python3.12/site-packages/litellm/llms/custom_httpx/http_handler.py", line 704, in post
    raise e
  File "/opt/anaconda3/envs/tau/lib/python3.12/site-packages/litellm/llms/custom_httpx/http_handler.py", line 686, in post
    response.raise_for_status()
  File "/opt/anaconda3/envs/tau/lib/python3.12/site-packages/httpx/_models.py", line 829, in raise_for_status
    raise HTTPStatusError(message, request=request, response=self)
httpx.HTTPStatusError: Server error '503 Service Unavailable' for url 'https://generativelanguage.googleapis.com/v1beta/models/gemini-2.0-flash:generateContent?key=AIzaSyDSTWd5f1SEuKkCxbbKCNOYtm1t-HP3SVg'
For more information check: https://developer.mozilla.org/en-US/docs/Web/HTTP/Status/503

During handling of the above exception, another exception occurred:

Traceback (most recent call last):
  File "/opt/anaconda3/envs/tau/lib/python3.12/site-packages/litellm/main.py", line 2469, in completion
    response = vertex_chat_completion.completion(  # type: ignore
               ^^^^^^^^^^^^^^^^^^^^^^^^^^^^^^^^^^^^^^^^^^^^^^^^^^
  File "/opt/anaconda3/envs/tau/lib/python3.12/site-packages/litellm/llms/vertex_ai/gemini/vertex_and_google_ai_studio_gemini.py", line 1715, in completion
    raise VertexAIError(
litellm.llms.vertex_ai.common_utils.VertexAIError: {
  "error": {
    "code": 503,
    "message": "The model is overloaded. Please try again later.",
    "status": "UNAVAILABLE"
  }
}


During handling of the above exception, another exception occurred:

Traceback (most recent call last):
  File "/Users/xuanfeiren/Documents/tau-bench/Trace/opto/optimizers/optoprime.py", line 624, in call_llm
    response = self.llm(messages=messages, max_tokens=max_tokens, response_format=response_format)
               ^^^^^^^^^^^^^^^^^^^^^^^^^^^^^^^^^^^^^^^^^^^^^^^^^^^^^^^^^^^^^^^^^^^^^^^^^^^^^^^^^^^
  File "/Users/xuanfeiren/Documents/tau-bench/Trace/opto/utils/llm.py", line 45, in __call__
    return self.model(*args, **kwargs)
           ^^^^^^^^^^^^^^^^^^^^^^^^^^^
  File "/Users/xuanfeiren/Documents/tau-bench/Trace/opto/utils/llm.py", line 197, in <lambda>
    return lambda *args, **kwargs: self._model(*args, **kwargs)
                                   ^^^^^^^^^^^^^^^^^^^^^^^^^^^^
  File "/Users/xuanfeiren/Documents/tau-bench/Trace/opto/utils/llm.py", line 187, in <lambda>
    return lambda *args, **kwargs: litellm.completion(model_name, *args, **kwargs)
                                   ^^^^^^^^^^^^^^^^^^^^^^^^^^^^^^^^^^^^^^^^^^^^^^^
  File "/opt/anaconda3/envs/tau/lib/python3.12/site-packages/litellm/utils.py", line 1285, in wrapper
    raise e
  File "/opt/anaconda3/envs/tau/lib/python3.12/site-packages/litellm/utils.py", line 1163, in wrapper
    result = original_function(*args, **kwargs)
             ^^^^^^^^^^^^^^^^^^^^^^^^^^^^^^^^^^
  File "/opt/anaconda3/envs/tau/lib/python3.12/site-packages/litellm/main.py", line 3264, in completion
    raise exception_type(
          ^^^^^^^^^^^^^^^
  File "/opt/anaconda3/envs/tau/lib/python3.12/site-packages/litellm/litellm_core_utils/exception_mapping_utils.py", line 2239, in exception_type
    raise e
  File "/opt/anaconda3/envs/tau/lib/python3.12/site-packages/litellm/litellm_core_utils/exception_mapping_utils.py", line 1230, in exception_type
    raise litellm.InternalServerError(
litellm.exceptions.InternalServerError: litellm.InternalServerError: litellm.InternalServerError: VertexAIException - {
  "error": {
    "code": 503,
    "message": "The model is overloaded. Please try again later.",
    "status": "UNAVAILABLE"
  }
}


During handling of the above exception, another exception occurred:

Traceback (most recent call last):
  File "/opt/anaconda3/envs/tau/lib/python3.12/site-packages/litellm/llms/vertex_ai/gemini/vertex_and_google_ai_studio_gemini.py", line 1711, in completion
    response = client.post(url=url, headers=headers, json=data)  # type: ignore
               ^^^^^^^^^^^^^^^^^^^^^^^^^^^^^^^^^^^^^^^^^^^^^^^^
  File "/opt/anaconda3/envs/tau/lib/python3.12/site-packages/litellm/llms/custom_httpx/http_handler.py", line 704, in post
    raise e
  File "/opt/anaconda3/envs/tau/lib/python3.12/site-packages/litellm/llms/custom_httpx/http_handler.py", line 686, in post
    response.raise_for_status()
  File "/opt/anaconda3/envs/tau/lib/python3.12/site-packages/httpx/_models.py", line 829, in raise_for_status
    raise HTTPStatusError(message, request=request, response=self)
httpx.HTTPStatusError: Server error '503 Service Unavailable' for url 'https://generativelanguage.googleapis.com/v1beta/models/gemini-2.0-flash:generateContent?key=AIzaSyDSTWd5f1SEuKkCxbbKCNOYtm1t-HP3SVg'
For more information check: https://developer.mozilla.org/en-US/docs/Web/HTTP/Status/503

During handling of the above exception, another exception occurred:

Traceback (most recent call last):
  File "/opt/anaconda3/envs/tau/lib/python3.12/site-packages/litellm/main.py", line 2469, in completion
    response = vertex_chat_completion.completion(  # type: ignore
               ^^^^^^^^^^^^^^^^^^^^^^^^^^^^^^^^^^^^^^^^^^^^^^^^^^
  File "/opt/anaconda3/envs/tau/lib/python3.12/site-packages/litellm/llms/vertex_ai/gemini/vertex_and_google_ai_studio_gemini.py", line 1715, in completion
    raise VertexAIError(
litellm.llms.vertex_ai.common_utils.VertexAIError: {
  "error": {
    "code": 503,
    "message": "The model is overloaded. Please try again later.",
    "status": "UNAVAILABLE"
  }
}


During handling of the above exception, another exception occurred:

Traceback (most recent call last):
  File "/Users/xuanfeiren/Documents/tau-bench/tau_agent_opt.py", line 501, in main
    algorithm.train(**train_params)
  File "/Users/xuanfeiren/Documents/tau-bench/Trace/opto/trainer/algorithms/basic_algorithms.py", line 161, in train
    score = self.update(outputs, verbose=verbose, num_threads=num_threads, **kwargs)
            ^^^^^^^^^^^^^^^^^^^^^^^^^^^^^^^^^^^^^^^^^^^^^^^^^^^^^^^^^^^^^^^^^^^^^^^^
  File "/Users/xuanfeiren/Documents/tau-bench/Trace/opto/trainer/algorithms/basic_algorithms.py", line 301, in update
    self.optimizer_step(verbose=verbose, num_threads=num_threads, **kwargs)  # update the agent
    ^^^^^^^^^^^^^^^^^^^^^^^^^^^^^^^^^^^^^^^^^^^^^^^^^^^^^^^^^^^^^^^^^^^^^^^
  File "/Users/xuanfeiren/Documents/tau-bench/Trace/opto/trainer/algorithms/basic_algorithms.py", line 309, in optimizer_step
    return self.optimizer.step(bypassing=bypassing, verbose=verbose, **kwargs)
           ^^^^^^^^^^^^^^^^^^^^^^^^^^^^^^^^^^^^^^^^^^^^^^^^^^^^^^^^^^^^^^^^^^^
  File "/Users/xuanfeiren/Documents/tau-bench/Trace/opto/optimizers/optimizer.py", line 56, in step
    update_dict = self.propose(*args, **kwargs)
                  ^^^^^^^^^^^^^^^^^^^^^^^^^^^^^
  File "/Users/xuanfeiren/Documents/tau-bench/Trace/opto/optimizers/optimizer.py", line 72, in propose
    return self._step(*args, **kwargs)
           ^^^^^^^^^^^^^^^^^^^^^^^^^^^
  File "/Users/xuanfeiren/Documents/tau-bench/Trace/opto/optimizers/optoprime.py", line 504, in _step
    response = self.call_llm(
               ^^^^^^^^^^^^^^
  File "/Users/xuanfeiren/Documents/tau-bench/Trace/opto/optimizers/optoprime.py", line 626, in call_llm
    response = self.llm(messages=messages, max_tokens=max_tokens)
               ^^^^^^^^^^^^^^^^^^^^^^^^^^^^^^^^^^^^^^^^^^^^^^^^^^
  File "/Users/xuanfeiren/Documents/tau-bench/Trace/opto/utils/llm.py", line 45, in __call__
    return self.model(*args, **kwargs)
           ^^^^^^^^^^^^^^^^^^^^^^^^^^^
  File "/Users/xuanfeiren/Documents/tau-bench/Trace/opto/utils/llm.py", line 197, in <lambda>
    return lambda *args, **kwargs: self._model(*args, **kwargs)
                                   ^^^^^^^^^^^^^^^^^^^^^^^^^^^^
  File "/Users/xuanfeiren/Documents/tau-bench/Trace/opto/utils/llm.py", line 187, in <lambda>
    return lambda *args, **kwargs: litellm.completion(model_name, *args, **kwargs)
                                   ^^^^^^^^^^^^^^^^^^^^^^^^^^^^^^^^^^^^^^^^^^^^^^^
  File "/opt/anaconda3/envs/tau/lib/python3.12/site-packages/litellm/utils.py", line 1285, in wrapper
    raise e
  File "/opt/anaconda3/envs/tau/lib/python3.12/site-packages/litellm/utils.py", line 1163, in wrapper
    result = original_function(*args, **kwargs)
             ^^^^^^^^^^^^^^^^^^^^^^^^^^^^^^^^^^
  File "/opt/anaconda3/envs/tau/lib/python3.12/site-packages/litellm/main.py", line 3264, in completion
    raise exception_type(
          ^^^^^^^^^^^^^^^
  File "/opt/anaconda3/envs/tau/lib/python3.12/site-packages/litellm/litellm_core_utils/exception_mapping_utils.py", line 2239, in exception_type
    raise e
  File "/opt/anaconda3/envs/tau/lib/python3.12/site-packages/litellm/litellm_core_utils/exception_mapping_utils.py", line 1230, in exception_type
    raise litellm.InternalServerError(
litellm.exceptions.InternalServerError: litellm.InternalServerError: litellm.InternalServerError: VertexAIException - {
  "error": {
    "code": 503,
    "message": "The model is overloaded. Please try again later.",
    "status": "UNAVAILABLE"
  }
}
