2025-07-10 14:49:49,634 INFO    MainThread:19196 [wandb_setup.py:_flush():81] Current SDK version is 0.20.1
2025-07-10 14:49:49,634 INFO    MainThread:19196 [wandb_setup.py:_flush():81] Configure stats pid to 19196
2025-07-10 14:49:49,634 INFO    MainThread:19196 [wandb_setup.py:_flush():81] Loading settings from /Users/xuanfeiren/.config/wandb/settings
2025-07-10 14:49:49,634 INFO    MainThread:19196 [wandb_setup.py:_flush():81] Loading settings from /Users/xuanfeiren/Documents/tau-bench/wandb/settings
2025-07-10 14:49:49,634 INFO    MainThread:19196 [wandb_setup.py:_flush():81] Loading settings from environment variables
2025-07-10 14:49:49,634 INFO    MainThread:19196 [wandb_init.py:setup_run_log_directory():703] Logging user logs to ./logs/wandb/run-20250710_144949-7wkcy1vd/logs/debug.log
2025-07-10 14:49:49,634 INFO    MainThread:19196 [wandb_init.py:setup_run_log_directory():704] Logging internal logs to ./logs/wandb/run-20250710_144949-7wkcy1vd/logs/debug-internal.log
2025-07-10 14:49:49,634 INFO    MainThread:19196 [wandb_init.py:init():831] calling init triggers
2025-07-10 14:49:49,634 INFO    MainThread:19196 [wandb_init.py:init():836] wandb.init called with sweep_config: {}
config: {'_wandb': {}}
2025-07-10 14:49:49,634 INFO    MainThread:19196 [wandb_init.py:init():872] starting backend
2025-07-10 14:49:49,845 INFO    MainThread:19196 [wandb_init.py:init():875] sending inform_init request
2025-07-10 14:49:49,868 INFO    MainThread:19196 [wandb_init.py:init():883] backend started and connected
2025-07-10 14:49:49,869 INFO    MainThread:19196 [wandb_init.py:init():956] updated telemetry
2025-07-10 14:49:49,882 INFO    MainThread:19196 [wandb_init.py:init():980] communicating run to backend with 90.0 second timeout
2025-07-10 14:49:50,444 INFO    MainThread:19196 [wandb_init.py:init():1032] starting run threads in backend
2025-07-10 14:49:50,529 INFO    MainThread:19196 [wandb_run.py:_console_start():2453] atexit reg
2025-07-10 14:49:50,529 INFO    MainThread:19196 [wandb_run.py:_redirect():2301] redirect: wrap_raw
2025-07-10 14:49:50,529 INFO    MainThread:19196 [wandb_run.py:_redirect():2370] Wrapping output streams.
2025-07-10 14:49:50,529 INFO    MainThread:19196 [wandb_run.py:_redirect():2393] Redirects installed.
2025-07-10 14:49:50,531 INFO    MainThread:19196 [wandb_init.py:init():1078] run started, returning control to user process
2025-07-10 14:53:43,043 INFO    MsgRouterThr:19196 [mailbox.py:close():129] [no run ID] Closing mailbox, abandoning 1 handles.
2025-07-10 14:53:43,261 ERROR   ThreadPoolExecutor-6_6:19196 [redirect.py:_on_write():664] [no run ID] error in stdout callback
Traceback (most recent call last):
  File "/Users/xuanfeiren/Documents/tau-bench/tau_agent_opt.py", line 126, in solve
    res = completion(**completion_kwargs)
          ^^^^^^^^^^^^^^^^^^^^^^^^^^^^^^^
  File "/opt/anaconda3/envs/tau/lib/python3.12/site-packages/litellm/utils.py", line 1285, in wrapper
    raise e
  File "/opt/anaconda3/envs/tau/lib/python3.12/site-packages/litellm/utils.py", line 1216, in wrapper
    executor.submit(
  File "/opt/anaconda3/envs/tau/lib/python3.12/concurrent/futures/thread.py", line 171, in submit
    raise RuntimeError('cannot schedule new futures after shutdown')
RuntimeError: cannot schedule new futures after shutdown

During handling of the above exception, another exception occurred:

Traceback (most recent call last):
  File "/opt/anaconda3/envs/tau/lib/python3.12/site-packages/wandb/sdk/lib/redirect.py", line 662, in _on_write
    cb(written_data)
  File "/opt/anaconda3/envs/tau/lib/python3.12/site-packages/wandb/sdk/wandb_run.py", line 2374, in <lambda>
    lambda data: self._console_raw_callback("stdout", data),
                 ^^^^^^^^^^^^^^^^^^^^^^^^^^^^^^^^^^^^^^^^^^
  File "/opt/anaconda3/envs/tau/lib/python3.12/site-packages/wandb/sdk/wandb_run.py", line 391, in wrapper
    return func(self, *args, **kwargs)
           ^^^^^^^^^^^^^^^^^^^^^^^^^^^
  File "/opt/anaconda3/envs/tau/lib/python3.12/site-packages/wandb/sdk/wandb_run.py", line 449, in wrapper_fn
    return func(self, *args, **kwargs)
           ^^^^^^^^^^^^^^^^^^^^^^^^^^^
  File "/opt/anaconda3/envs/tau/lib/python3.12/site-packages/wandb/sdk/wandb_run.py", line 1561, in _console_raw_callback
    self._backend.interface.publish_output_raw(name, data)
  File "/opt/anaconda3/envs/tau/lib/python3.12/site-packages/wandb/sdk/interface/interface.py", line 772, in publish_output_raw
    self._publish_output_raw(o)
  File "/opt/anaconda3/envs/tau/lib/python3.12/site-packages/wandb/sdk/interface/interface_shared.py", line 38, in _publish_output_raw
    self._publish(rec)
  File "/opt/anaconda3/envs/tau/lib/python3.12/site-packages/wandb/sdk/interface/interface_sock.py", line 39, in _publish
    self._sock_client.send_record_publish(record)
  File "/opt/anaconda3/envs/tau/lib/python3.12/site-packages/wandb/sdk/lib/sock_client.py", line 174, in send_record_publish
    self.send_server_request(server_req)
  File "/opt/anaconda3/envs/tau/lib/python3.12/site-packages/wandb/sdk/lib/sock_client.py", line 154, in send_server_request
    self._send_message(msg)
  File "/opt/anaconda3/envs/tau/lib/python3.12/site-packages/wandb/sdk/lib/sock_client.py", line 151, in _send_message
    self._sendall_with_error_handle(header + data)
  File "/opt/anaconda3/envs/tau/lib/python3.12/site-packages/wandb/sdk/lib/sock_client.py", line 130, in _sendall_with_error_handle
    sent = self._sock.send(data)
           ^^^^^^^^^^^^^^^^^^^^^
BrokenPipeError: [Errno 32] Broken pipe
